Workbook
Name UPDATE: 'DATA SHEET'!$E$1

Sheet DATA SHEET
A1: COMPANY NAME | B1: TATA MOTORS LTD | E1: =IF(B2<>B3,"A NEW VERSION OF THE WORKSHEET IS AVAILABLE","")
A2: LATEST VERSION | B2: 2.1 | E2: PLEASE DO NOT MAKE ANY CHANGES TO THIS SHEET
A3: CURRENT VERSION | B3: 2.1
A5: META
A6: Number of shares | B6: =IF(B9>0,B9/B8,0) -> 0
A7: Face Value | B7: 2
A8: Current Price | B8: 697.3
A9: Market Capitalization | B9: 256689.37
A15: PROFIT & LOSS
A16: Report Date | B16: 42094 | C16: 42460 | D16: 42825 | E16: 43190 | F16: 43555 | G16: 43921 | H16: 44286 | I16: 44651 | J16: 45016 | K16: 45382
A17: Sales | B17: 263158.98 | C17: 273045.6 | D17: 269692.51 | E17: 291550.48 | F17: 301938.4 | G17: 261067.97 | H17: 249794.75 | I17: 278453.62 | J17: 345966.97 | K17: 437927.77
A18: Raw Material Cost | B18: 163250.36 | C18: 166134.01 | D18: 173294.08 | E18: 187896.58 | F18: 194267.91 | G18: 164899.82 | H18: 153607.36 | I18: 179295.33 | J18: 231251.26 | K18: 274321.23
A19: Change in Inventory | B19: 3330.35 | C19: 2750.99 | D19: 7399.92 | E19: 2046.58 | F19: -2053.28 | G19: -2231.19 | H19: -4684.16 | I19: -1590.49 | J19: 4781.62 | K19: 1565.53
A20: Power and Fuel | B20: 1121.75 | C20: 1143.63 | D20: 1159.82 | E20: 1308.08 | F20: 1585.93 | G20: 1264.95 | H20: 1112.87 | I20: 2178.29 | J20: 2513.33 | K20: 2195.12
A21: Other Mfr. Exp | B21: 16173.17 | C21: 12101.53 | D21: 10067.37 | E21: 10971.66 | F21: 11694.54 | G21: 11541.51 | H21: 8273.17 | I21: 9427.38 | J21: 11765.97 | K21: 17114.33
A22: Employee Cost | B22: 25641.95 | C22: 28880.89 | D22: 28332.89 | E22: 30300.09 | F22: 33243.87 | G22: 30438.6 | H22: 27648.48 | I22: 30808.52 | J22: 33654.7 | K22: 42486.64
A23: Selling and admin | B23: 23603.01 | C23: 21991.9 | D23: 30039.38 | E23: 31004.58 | F23: 32719.8 | G23: 29248.32 | H23: 23015.79 | I23: 29205.4 | J23: 34839.19 | K23: 42765.33
A24: Other Expenses | B24: -2539.56 | C24: 7149.38 | D24: 4610.2 | E24: 658.39 | F24: 1708.74 | G24: 3456.51 | H24: -834.51 | I24: 1228.12 | J24: 4908.34 | K24: 1072.31
A25: Other Income | B25: 714.03 | C25: -2669.62 | D25: 1869.1 | E25: 5932.73 | F25: -26686.25 | G25: 101.71 | H25: -11117.83 | I25: 2424.05 | J25: 6663.97 | K25: 5672.66
A26: Depreciation | B26: 13388.63 | C26: 16710.78 | D26: 17904.99 | E26: 21553.59 | F26: 23590.63 | G26: 21425.43 | H26: 23546.71 | I26: 24835.69 | J26: 24860.36 | K26: 27270.13
A27: Interest | B27: 4861.49 | C27: 4889.08 | D27: 4238.01 | E27: 4681.79 | F27: 5758.6 | G27: 7243.33 | H27: 8097.17 | I27: 9311.86 | J27: 10225.48 | K27: 9985.76
... A30: Net profit | B30: 13986.29 | C30: 11579.31 | D30: 7454.36 | E30: 8988.91 | F30: -28826.23 | G30: -12070.85 | H30: -13451.39 | I30: -11441.47 | J30: 2414.29 | K30: 31399.09
A31: Dividend Amount | C31: 67.92 | J31: 766.02 | K31: 2299.5
A40: Quarters
A41: Report Date | B41: 44834 | C41: 44926 | D41: 45016 | E41: 45107 | F41: 45199 | G41: 45291 | H41: 45382 | I41: 45473 | J41: 45565 | K41: 45657
A42: Sales | B42: 79611.37 | C42: 88488.59 | D42: 105932.35 | E42: 102236 | F42: 105129 | G42: 110577 | H42: 119986 | I42: 108048 | J42: 101450 | K42: 113575
A43: Expenses | B43: 74039.06 | C43: 77668.35 | D43: 92817.95 | E43: 89019 | F43: 91362 | G43: 95159 | H43: 102851 | I43: 92263 | J43: 89291 | K43: 100532
A44: Other Income | B44: 1351.14 | C44: 1129.98 | D44: 1452.86 | E44: 895 | F44: 1557 | G44: 1604 | H44: 1619 | I44: 1747 | J44: 1647 | K44: 1764
A45: Depreciation | B45: 5897.34 | C45: 6071.78 | D45: 7050.2 | E45: 6633 | F45: 6637 | G45: 6850 | H45: 7151 | I45: 6574 | J45: 6005 | K45: 5408
A46: Interest | B46: 2487.26 | C46: 2675.83 | D46: 2641.67 | E46: 2615 | F46: 2652 | G46: 2485 | H46: 2234 | I46: 2088 | J46: 2034 | K46: 1725
A47: Profit before tax | B47: -1461.15 | C47: 3202.61 | D47: 4875.39 | E47: 4864 | F47: 6035 | G47: 7687 | H47: 9369 | I47: 8870 | J47: 5767 | K47: 7674
A48: Tax | B48: -457.08 | C48: 262.83 | D48: -620.65 | E48: 1563 | F48: 2203 | G48: 542 | H48: -8160 | I48: 3178 | J48: 2317 | K48: 2096
A49: Net profit | B49: -944.61 | C49: 2957.71 | D49: 5407.79 | E49: 3203 | F49: 3764 | G49: 7025 | H49: 17407 | I49: 5566 | J49: 3343 | K49: 5451
A50: Operating Profit | B50: 5572.31 | C50: 10820.24 | D50: 13114.4 | E50: 13217 | F50: 13767 | G50: 15418 | H50: 17135 | I50: 15785 | J50: 12159 | K50: 13043
A55: BALANCE SHEET
A56: Report Date | B56: 42094 | C56: 42460 | D56: 42825 | E56: 43190 | F56: 43555 | G56: 43921 | H56: 44286 | I56: 44651 | J56: 45016 | K56: 45382
A57: Equity Share Capital | B57: 643.78 | C57: 679.18 | D57: 679.22 | E57: 679.22 | F57: 679.22 | G57: 719.54 | H57: 765.81 | I57: 765.88 | J57: 766.02 | K57: 766.5
A58: Reserves | B58: 55618.14 | C58: 78273.23 | D58: 57382.67 | E58: 94748.69 | F58: 59500.34 | G58: 62358.99 | H58: 54480.91 | I58: 43795.36 | J58: 44555.77 | K58: 84151.52
A59: Borrowings | B59: 73610.39 | C59: 69359.96 | D59: 78603.98 | E59: 88950.47 | F59: 106175.34 | G59: 124787.64 | H59: 142130.57 | I59: 146449.03 | J59: 134113.44 | K59: 107262.5
A60: Other Liabilities | B60: 107442.48 | C60: 114871.75 | D60: 135914.49 | E60: 142813.43 | F60: 139348.59 | G60: 132313.22 | H60: 144192.62 | I60: 138051.22 | J60: 155239.2 | K60: 177340.09
...

Sheet HISTORICAL FS
B2: ="Historical Financial Data - "&'DATA SHEET'!B1 -> Historical Financial Data - TATA MOTORS LTD
B3: Years | C3: ='DATA SHEET'!B16 -> 42094 | D3: ='DATA SHEET'!C16 -> 42460 | E3: ='DATA SHEET'!D16 -> 42825 | F3: ='DATA SHEET'!E16 -> 43190 | G3: ='DATA SHEET'!F16 -> 43555 | H3: ='DATA SHEET'!G16 -> 43921 | I3: ='DATA SHEET'!H16 -> 44286 | J3: ='DATA SHEET'!I16 -> 44651 | ... L3: ='DATA SHEET'!K16 -> 45382 | M3: LTM
A4: # | B4: INCOME STATEMENT
B5: SALES | C5: =IFERROR('DATA SHEET'!B17,0) -> 263158.98 | D5: =IFERROR('DATA SHEET'!C17,0) -> 273045.6 | E5: =IFERROR('DATA SHEET'!D17,0) -> 269692.51 | F5: =IFERROR('DATA SHEET'!E17,0) -> 291550.48 | G5: =IFERROR('DATA SHEET'!F17,0) -> 301938.4 | H5: =IFERROR('DATA SHEET'!G17,0) -> 261067.97 | I5: =IFERROR('DATA SHEET'!H17,0) -> 249794.75 | J5: =IFERROR('DATA SHEET'!I17,0) -> 278453.62 | ... L5: =IFERROR('DATA SHEET'!K17,0) -> 437927.77 | M5: =IFERROR(SUM('DATA SHEET'!H42:K42),0) -> 443059
B6: SALES GROWTH | D6: =D5/C5-1 -> 0.037569001 | E6: =E5/D5-1 -> -0.01228033 | F6: =F5/E5-1 -> 0.081047746 | G6: =G5/F5-1 -> 0.035629919 | H6: =H5/G5-1 -> -0.13536016 | I6: =I5/H5-1 -> -0.043181168 | J6: =J5/I5-1 -> 0.11472967 | K6: =K5/J5-1 -> 0.24245815 | L6: =L5/K5-1 -> 0.26580803
B8: COGS | C8: =IFERROR(SUM('DATA SHEET'!B18,'DATA SHEET'!B20,'DATA SHEET'!B21,'DATA SHEET'!B22)-1*'DATA SHEET'!B19,0) -> 202856.88 | D8: =IFERROR(SUM('DATA SHEET'!C18,'DATA SHEET'!C20,'DATA SHEET'!C21,'DATA SHEET'!C22)-1*'DATA SHEET'!C19,0) -> 205509.07 | E8: =IFERROR(SUM('DATA SHEET'!D18,'DATA SHEET'!D20,'DATA SHEET'!D21,'DATA SHEET'!D22)-1*'DATA SHEET'!D19,0) -> 205454.24 | F8: =IFERROR(SUM('DATA SHEET'!E18,'DATA SHEET'!E20,'DATA SHEET'!E21,'DATA SHEET'!E22)-1*'DATA SHEET'!E19,0) -> 228429.83 | G8: =IFERROR(SUM('DATA SHEET'!F18,'DATA SHEET'!F20,'DATA SHEET'!F21,'DATA SHEET'!F22)-1*'DATA SHEET'!F19,0) -> 242845.53 | H8: =IFERROR(SUM('DATA SHEET'!G18,'DATA SHEET'!G20,'DATA SHEET'!G21,'DATA SHEET'!G22)-1*'DATA SHEET'!G19,0) -> 210376.07 | I8: =IFERROR(SUM('DATA SHEET'!H18,'DATA SHEET'!H20,'DATA SHEET'!H21,'DATA SHEET'!H22)-1*'DATA SHEET'!H19,0) -> 195326.04 | J8: =IFERROR(SUM('DATA SHEET'!I18,'DATA SHEET'!I20,'DATA SHEET'!I21,'DATA SHEET'!I22)-1*'DATA SHEET'!I19,0) -> 223300.01 | ... L8: =IFERROR(SUM('DATA SHEET'!K18,'DATA SHEET'!K20,'DATA SHEET'!K21,'DATA SHEET'!K22)-1*'DATA SHEET'!K19,0) -> 334551.79
B9: COGS % SALES | C9: =C8/C5 -> 0.77085297 | D9: =D8/D5 -> 0.75265476 | E9: =E8/E5 -> 0.76180922 | F9: =F8/F5 -> 0.7835001 | G9: =G8/G5 -> 0.80428833 | H9: =H8/H5 -> 0.80582873 | I9: =I8/I5 -> 0.78194614 | J9: =J8/J5 -> 0.80192892 | ... L9: =L8/L5 -> 0.76394285
B11: GROSS PROFIT | C11: =C5-C8 -> 60302.1 | D11: =D5-D8 -> 67536.53 | E11: =E5-E8 -> 64238.27 | F11: =F5-F8 -> 63120.65 | G11: =G5-G8 -> 59092.87 | H11: =H5-H8 -> 50691.9 | I11: =I5-I8 -> 54468.71 | J11: =J5-J8 -> 55153.61 | ... L11: =L5-L8 -> 103375.98
B12: GROSS PROFIT MARGIN
B14: SELLING AND GEN. EXP | C14: =IFERROR(SUM('DATA SHEET'!B23,'DATA SHEET'!B24),0) -> 21063.45 | D14: =IFERROR(SUM('DATA SHEET'!C23,'DATA SHEET'!C24),0) -> 29141.28 | E14: =IFERROR(SUM('DATA SHEET'!D23,'DATA SHEET'!D24),0) -> 34649.58 | F14: =IFERROR(SUM('DATA SHEET'!E23,'DATA SHEET'!E24),0) -> 31662.97 | G14: =IFERROR(SUM('DATA SHEET'!F23,'DATA SHEET'!F24),0) -> 34428.54 | H14: =IFERROR(SUM('DATA SHEET'!G23,'DATA SHEET'!G24),0) -> 32704.83 | I14: =IFERROR(SUM('DATA SHEET'!H23,'DATA SHEET'!H24),0) -> 22181.28 | J14: =IFERROR(SUM('DATA SHEET'!I23,'DATA SHEET'!I24),0) -> 30433.52 | ... L14: =IFERROR(SUM('DATA SHEET'!K23,'DATA SHEET'!K24),0) -> 43837.64
B15: S & G % SALES | C15: =C14/C5 -> 0.08004078 | D15: =D14/D5 -> 0.10672679 | E15: =E14/E5 -> 0.1284781 | F15: =F14/F5 -> 0.10860202 | G15: =G14/G5 -> 0.11402505 | H15: =H14/H5 -> 0.12527324 | I15: =I14/I5 -> 0.088798023 | J15: =J14/J5 -> 0.10929475 | ... L15: =L14/L5 -> 0.10010244
B17: EBITDA | C17: =C11-C14 -> 39238.65 | D17: =D11-D14 -> 38395.25 | E17: =E11-E14 -> 29588.69 | F17: =F11-F14 -> 31457.68 | G17: =G11-G14 -> 24664.33 | H17: =H11-H14 -> 17987.07 | I17: =I11-I14 -> 32287.43 | J17: =J11-J14 -> 24720.09 | ... L17: =L11-L14 -> 59538.34
B18: EBITDA MARGIN | C18: =C17/C5 -> 0.14910626 | D18: =D17/D5 -> 0.14061845 | E18: =E17/E5 -> 0.10971269 | F18: =F17/F5 -> 0.10789788 | G18: =G17/G5 -> 0.081686629 | H18: =H17/H5 -> 0.068898034 | I18: =I17/I5 -> 0.12925584 | J18: =J17/J5 -> 0.088776328 | ... L18: =L17/L5 -> 0.1359547
B20: INTEREST | C20: =IFERROR('DATA SHEET'!B27,0) -> 4861.49 | D20: =IFERROR('DATA SHEET'!C27,0) -> 4889.08 | E20: =IFERROR('DATA SHEET'!D27,0) -> 4238.01 | F20: =IFERROR('DATA SHEET'!E27,0) -> 4681.79 | G20: =IFERROR('DATA SHEET'!F27,0) -> 5758.6 | H20: =IFERROR('DATA SHEET'!G27,0) -> 7243.33 | I20: =IFERROR('DATA SHEET'!H27,0) -> 8097.17 | J20: =IFERROR('DATA SHEET'!I27,0) -> 9311.86 | ... L20: =IFERROR('DATA SHEET'!K27,0) -> 9985.76
B21: INTEREST % SALES | C21: =C20/C5 -> 0.018473586 | D21: =D20/D5 -> 0.017905727 | E21: =E20/E5 -> 0.01571423 | F21: =F20/F5 -> 0.016058248 | G21: =G20/G5 -> 0.019072102 | H21: =H20/H5 -> 0.027744997 | I21: =I20/I5 -> 0.032415293 | J21: =J20/J5 -> 0.033441332 | ... L21: =L20/L5 -> 0.022802299
B23: DEPRICIATION | C23: =IFERROR('DATA SHEET'!B26,0) -> 13388.63 | D23: =IFERROR('DATA SHEET'!C26,0) -> 16710.78 | E23: =IFERROR('DATA SHEET'!D26,0) -> 17904.99 | F23: =IFERROR('DATA SHEET'!E26,0) -> 21553.59 | G23: =IFERROR('DATA SHEET'!F26,0) -> 23590.63 | H23: =IFERROR('DATA SHEET'!G26,0) -> 21425.43 | I23: =IFERROR('DATA SHEET'!H26,0) -> 23546.71 | J23: =IFERROR('DATA SHEET'!I26,0) -> 24835.69 | ... L23: =IFERROR('DATA SHEET'!K26,0) -> 27270.13
B24: DEP % SALES | C24: =C23/C5 -> 0.050876584 | D24: =D23/D5 -> 0.061201426 | E24: =E23/E5 -> 0.066390387 | F24: =F23/F5 -> 0.073927472 | G24: =G23/G5 -> 0.078130605 | H24: =H23/H5 -> 0.082068398 | I24: =I23/I5 -> 0.094264231 | J24: =J23/J5 -> 0.089191478 | ... L24: =L23/L5 -> 0.06227084
B26: EARNING BEFORE TAX | C26: =IFERROR('DATA SHEET'!B28,0) -> 21702.56 | D26: =IFERROR('DATA SHEET'!C28,0) -> 14125.77 | E26: =IFERROR('DATA SHEET'!D28,0) -> 9314.79 | F26: =IFERROR('DATA SHEET'!E28,0) -> 11155.03 | G26: =IFERROR('DATA SHEET'!F28,0) -> -31371.15 | H26: =IFERROR('DATA SHEET'!G28,0) -> -10579.98 | I26: =IFERROR('DATA SHEET'!H28,0) -> -10474.28 | J26: =IFERROR('DATA SHEET'!I28,0) -> -7003.41 | ... L26: =IFERROR('DATA SHEET'!K28,0) -> 27955.11
B27: EBT % SALES | C27: =C26/C5 -> 0.082469388 | D27: =D26/D5 -> 0.051734106 | E27: =E26/E5 -> 0.034538557 | F27: =F26/F5 -> 0.038261059 | G27: =G26/G5 -> -0.10389917 | H27: =H26/H5 -> -0.040525768 | I27: =I26/I5 -> -0.041931546 | J27: =J26/J5 -> -0.025151083 | ... L27: =L26/L5 -> 0.063834979
B29: TAX | C29: =IFERROR('DATA SHEET'!B29,0) -> 7642.91 | D29: =IFERROR('DATA SHEET'!C29,0) -> 3025.05 | E29: =IFERROR('DATA SHEET'!D29,0) -> 3251.23 | F29: =IFERROR('DATA SHEET'!E29,0) -> 4341.93 | G29: =IFERROR('DATA SHEET'!F29,0) -> -2437.45 | H29: =IFERROR('DATA SHEET'!G29,0) -> 395.25 | I29: =IFERROR('DATA SHEET'!H29,0) -> 2541.86 | J29: =IFERROR('DATA SHEET'!I29,0) -> 4231.29 | ... L29: =IFERROR('DATA SHEET'!K29,0) -> -3851.64
B30: EFFECTIVE TAX RATE | C30: =C29/C26 -> 0.35216629 | D30: =D29/D26 -> 0.21415116 | E30: =E29/E26 -> 0.34903954 | F30: =F29/F26 -> 0.38923517 | G30: =G29/G26 -> 0.077697184 | H30: =H29/H26 -> -0.037358294 | I30: =I29/I26 -> -0.24267635 | J30: =J29/J26 -> -0.60417568 | ... L30: =L29/L26 -> -0.13777946
B32: NET PROFIT | C32: =C26-C29 -> 14059.65 | D32: =D26-D29 -> 11100.72 | E32: =E26-E29 -> 6063.56 | F32: =F26-F29 -> 6813.1 | G32: =G26-G29 -> -28933.7 | H32: =H26-H29 -> -10975.23 | I32: =I26-I29 -> -13016.14 | J32: =J26-J29 -> -11234.7 | ... L32: =L26-L29 -> 31806.75
B33: NET MARGIN | C33: =C32/C5 -> 0.05342645 | D33: =D32/D5 -> 0.040655187 | E33: =E32/E5 -> 0.022483235 | F33: =F32/F5 -> 0.023368509 | G33: =G32/G5 -> -0.0958265 | H33: =H32/H5 -> -0.042039742 | I33: =I32/I5 -> -0.05210734 | J33: =J32/J5 -> -0.040346755 | ... L33: =L32/L5 -> 0.072630128
B35: No. of Equity Shareholders Outstanding | C35: =IFERROR('DATA SHEET'!B93,0) -> 288.74 | D35: =IFERROR('DATA SHEET'!C93,0) -> 288.72 | E35: =IFERROR('DATA SHEET'!D93,0) -> 288.73 | F35: =IFERROR('DATA SHEET'!E93,0) -> 288.73 | G35: =IFERROR('DATA SHEET'!F93,0) -> 288.73 | H35: =IFERROR('DATA SHEET'!G93,0) -> 308.9 | I35: =IFERROR('DATA SHEET'!H93,0) -> 332.03 | J35: =IFERROR('DATA SHEET'!I93,0) -> 332.07 | ... L35: =IFERROR('DATA SHEET'!K93,0) -> 332.37
B37: EPS | C37: =C32/C35 -> 48.693115 | D37: =D32/D35 -> 38.448047 | E37: =E32/E35 -> 21.000797 | F37: =F32/F35 -> 23.596786 | G37: =G32/G35 -> -100.21023 | H37: =H32/H35 -> -35.530042 | I37: =I32/I35 -> -39.201699 | J37: =J32/J35 -> -33.832325 | ... L37: =L32/L35 -> 95.696814
B38: EPS GROWTH
B39: DPS | C39: =IFERROR('DATA SHEET'!B31/'HISTORICAL FS'!C35,0) -> 0 | D39: =IFERROR('DATA SHEET'!C31/'HISTORICAL FS'!D35,0) -> 0.23524522 | E39: =IFERROR('DATA SHEET'!D31/'HISTORICAL FS'!E35,0) -> 0 | F39: =IFERROR('DATA SHEET'!E31/'HISTORICAL FS'!F35,0) -> 0 | G39: =IFERROR('DATA SHEET'!F31/'HISTORICAL FS'!G35,0) -> 0 | H39: =IFERROR('DATA SHEET'!G31/'HISTORICAL FS'!H35,0) -> 0 | I39: =IFERROR('DATA SHEET'!H31/'HISTORICAL FS'!I35,0) -> 0 | J39: =IFERROR('DATA SHEET'!I31/'HISTORICAL FS'!J35,0) -> 0 | ... L39: =IFERROR('DATA SHEET'!K31/'HISTORICAL FS'!L35,0) -> 6.9184944
B40: DPS RATIO | C40: =IFERROR(C39/C37,0) -> 0 | D40: =IFERROR(D39/D37,0) -> 0.006118522 | E40: =IFERROR(E39/E37,0) -> 0 | F40: =IFERROR(F39/F37,0) -> 0 | G40: =IFERROR(G39/G37,0) -> 0 | H40: =IFERROR(H39/H37,0) -> 0 | I40: =IFERROR(I39/I37,0) -> 0 | J40: =IFERROR(J39/J37,0) -> 0 | ... L40: =IFERROR(L39/L37,0) -> 0.072295975
B42: RETAINED EARNING | C42: =IFERROR(1-C40,0) -> 1 | D42: =IFERROR(1-D40,0) -> 0.99388148 | E42: =IFERROR(1-E40,0) -> 1 | F42: =IFERROR(1-F40,0) -> 1 | G42: =IFERROR(1-G40,0) -> 1 | H42: =IFERROR(1-H40,0) -> 1 | I42: =IFERROR(1-I40,0) -> 1 | J42: =IFERROR(1-J40,0) -> 1 | ... L42: =IFERROR(1-L40,0) -> 0.92770403
C43: =IFERROR(IF(C37>C39,1-C40,0),0) -> 1 | D43: =IFERROR(IF(D37>D39,1-D40,0),0) -> 0.99388148 | E43: =IFERROR(IF(E37>E39,1-E40,0),0) -> 1 | F43: =IFERROR(IF(F37>F39,1-F40,0),0) -> 1 | G43: =IFERROR(IF(G37>G39,1-G40,0),0) -> 0 | H43: =IFERROR(IF(H37>H39,1-H40,0),0) -> 0 | I43: =IFERROR(IF(I37>I39,1-I40,0),0) -> 0 | J43: =IFERROR(IF(J37>J39,1-J40,0),0) -> 0 | ... L43: =IFERROR(IF(L37>L39,1-L40,0),0) -> 0.92770403
A45: # | B45: BALANCE SHEET
B46: Equity Share Capital | C46: =IFERROR('DATA SHEET'!B57,0) -> 643.78 | D46: =IFERROR('DATA SHEET'!C57,0) -> 679.18 | E46: =IFERROR('DATA SHEET'!D57,0) -> 679.22 | F46: =IFERROR('DATA SHEET'!E57,0) -> 679.22 | G46: =IFERROR('DATA SHEET'!F57,0) -> 679.22 | H46: =IFERROR('DATA SHEET'!G57,0) -> 719.54 | I46: =IFERROR('DATA SHEET'!H57,0) -> 765.81 | J46: =IFERROR('DATA SHEET'!I57,0) -> 765.88 | ... L46: =IFERROR('DATA SHEET'!K57,0) -> 766.5
B47: Reserves | C47: =IFERROR('DATA SHEET'!B58,0) -> 55618.14 | D47: =IFERROR('DATA SHEET'!C58,0) -> 78273.23 | E47: =IFERROR('DATA SHEET'!D58,0) -> 57382.67 | F47: =IFERROR('DATA SHEET'!E58,0) -> 94748.69 | G47: =IFERROR('DATA SHEET'!F58,0) -> 59500.34 | H47: =IFERROR('DATA SHEET'!G58,0) -> 62358.99 | I47: =IFERROR('DATA SHEET'!H58,0) -> 54480.91 | J47: =IFERROR('DATA SHEET'!I58,0) -> 43795.36 | ... L47: =IFERROR('DATA SHEET'!K58,0) -> 84151.52
B48: Borrowings | C48: =IFERROR('DATA SHEET'!B59,0) -> 73610.39 | D48: =IFERROR('DATA SHEET'!C59,0) -> 69359.96 | E48: =IFERROR('DATA SHEET'!D59,0) -> 78603.98 | F48: =IFERROR('DATA SHEET'!E59,0) -> 88950.47 | G48: =IFERROR('DATA SHEET'!F59,0) -> 106175.34 | H48: =IFERROR('DATA SHEET'!G59,0) -> 124787.64 | I48: =IFERROR('DATA SHEET'!H59,0) -> 142130.57 | J48: =IFERROR('DATA SHEET'!I59,0) -> 146449.03 | ... L48: =IFERROR('DATA SHEET'!K59,0) -> 107262.5
B49: Other Liabilities | C49: =IFERROR('DATA SHEET'!B60,0) -> 107442.48 | D49: =IFERROR('DATA SHEET'!C60,0) -> 114871.75 | E49: =IFERROR('DATA SHEET'!D60,0) -> 135914.49 | F49: =IFERROR('DATA SHEET'!E60,0) -> 142813.43 | G49: =IFERROR('DATA SHEET'!F60,0) -> 139348.59 | H49: =IFERROR('DATA SHEET'!G60,0) -> 132313.22 | I49: =IFERROR('DATA SHEET'!H60,0) -> 144192.62 | J49: =IFERROR('DATA SHEET'!I60,0) -> 138051.22 | ... L49: =IFERROR('DATA SHEET'!K60,0) -> 177340.09
B50: Total Liabilities | C50: =SUM(C46:C49) -> 237314.79 | D50: =SUM(D46:D49) -> 263184.12 | E50: =SUM(E46:E49) -> 272580.36 | F50: =SUM(F46:F49) -> 327191.81 | G50: =SUM(G46:G49) -> 305703.49 | H50: =SUM(H46:H49) -> 320179.39 | I50: =SUM(I46:I49) -> 341569.91 | J50: =SUM(J46:J49) -> 329061.49 | ... L50: =SUM(L46:L49) -> 369520.61
B52: Fixed Asset Net Block | C52: =IFERROR('DATA SHEET'!B62,0) -> 88479.49 | D52: =IFERROR('DATA SHEET'!C62,0) -> 107231.76 | E52: =IFERROR('DATA SHEET'!D62,0) -> 95944.08 | F52: =IFERROR('DATA SHEET'!E62,0) -> 121413.86 | G52: =IFERROR('DATA SHEET'!F62,0) -> 111234.47 | H52: =IFERROR('DATA SHEET'!G62,0) -> 127107.14 | I52: =IFERROR('DATA SHEET'!H62,0) -> 138707.61 | J52: =IFERROR('DATA SHEET'!I62,0) -> 138855.45 | ... L52: =IFERROR('DATA SHEET'!K62,0) -> 121285.46
B53: Capital Work in Progress | C53: =IFERROR('DATA SHEET'!B63,0) -> 28640.09 | D53: =IFERROR('DATA SHEET'!C63,0) -> 25918.94 | E53: =IFERROR('DATA SHEET'!D63,0) -> 33698.84 | F53: =IFERROR('DATA SHEET'!E63,0) -> 40033.5 | G53: =IFERROR('DATA SHEET'!F63,0) -> 31883.84 | H53: =IFERROR('DATA SHEET'!G63,0) -> 35622.29 | I53: =IFERROR('DATA SHEET'!H63,0) -> 20963.93 | J53: =IFERROR('DATA SHEET'!I63,0) -> 10251.09 | ... L53: =IFERROR('DATA SHEET'!K63,0) -> 35698.43
B54: Investments | C54: =IFERROR('DATA SHEET'!B64,0) -> 15336.74 | D54: =IFERROR('DATA SHEET'!C64,0) -> 23767.02 | E54: =IFERROR('DATA SHEET'!D64,0) -> 20337.92 | F54: =IFERROR('DATA SHEET'!E64,0) -> 20812.75 | G54: =IFERROR('DATA SHEET'!F64,0) -> 15770.72 | H54: =IFERROR('DATA SHEET'!G64,0) -> 16308.48 | I54: =IFERROR('DATA SHEET'!H64,0) -> 24620.28 | J54: =IFERROR('DATA SHEET'!I64,0) -> 29379.53 | ... L54: =IFERROR('DATA SHEET'!K64,0) -> 22971.07
B55: Other Assets | C55: ='DATA SHEET'!B65-SUM('DATA SHEET'!B67:B69) -> 30891.17 | D55: ='DATA SHEET'!C65-SUM('DATA SHEET'!C67:C69) -> 29579.36 | E55: ='DATA SHEET'!D65-SUM('DATA SHEET'!D67:D69) -> 37360.78 | F55: ='DATA SHEET'!E65-SUM('DATA SHEET'!E67:E69) -> 48286.86 | G55: ='DATA SHEET'!F65-SUM('DATA SHEET'!F67:F69) -> 56155.74 | H55: ='DATA SHEET'!G65-SUM('DATA SHEET'!G67:G69) -> 58784.94 | I55: ='DATA SHEET'!H65-SUM('DATA SHEET'!H67:H69) -> 61717.96 | J55: ='DATA SHEET'!I65-SUM('DATA SHEET'!I67:I69) -> 62223.77 | ... L55: ='DATA SHEET'!K65-SUM('DATA SHEET'!K67:K69) -> 79018.86
...

Sheet CASH FLOW DATA
C2: 41334 | D2: 41699 | E2: 42064 | F2: 42430 | G2: 42795 | H2: 43160 | I2: 43525 | J2: 43891 | K2: 44256 | L2: 44621 | M2: 44986 | N2: 45352
B3: Cash from Operating Activity - | C3: 22163 | D3: 36151 | E3: 35531 | F3: 37900 | G3: 30199 | H3: 23857 | I3: 18891 | J3: 26633 | K3: 29001 | L3: 14283 | M3: 35388 | N3: 67915
B4: Profit from operations | C4: 24406 | D4: 36303 | E4: 43397 | F4: 38626 | G4: 28840 | H4: 33312 | I4: 28771 | J4: 23352 | K4: 31198 | L4: 26943 | M4: 41694 | N4: 65106
B5: Receivables | C5: -5177 | D5: 445 | E5: -3179 | F5: -2223 | G5: -4152 | H5: -10688 | I5: -9109 | J5: 9950 | K5: -5505 | L5: 185 | M5: -2213 | N5: -1875
B6: Inventory | C6: -2656 | D6: -2853 | E6: -3692 | F6: -5743 | G6: -6621 | H6: -3560 | I6: 2069 | J6: 2326 | K6: 3814 | L6: 472 | M6: -5665 | N6: -7265
B7: Payables | C7: 8132 | D7: 4694 | E7: 3598 | F7: 3947 | G7: 9301 | H7: 7320 | I7: -4692 | J7: -8085 | K7: 5748 | L7: -7012 | M7: 6945 | N7: 13706
B8: Loans Advances | C8: 0 | D8: 0 | E8: 0 | F8: -520 | G8: 0 | H8: 0 | I8: 0 | J8: 0 | K8: 0 | L8: 0 | M8: 0 | N8: 0
B9: Other WC items | C9: -303 | D9: 1870 | E9: -398 | F9: 5852 | G9: 4727 | H9: 494 | I9: 4512 | J9: 875 | K9: -4150 | L9: -4396 | M9: -2194 | N9: 2760
B10: Working capital changes | C10: -3 | D10: 4157 | E10: -3672 | F10: 1313 | G10: 3254 | H10: -6434 | I10: -7221 | J10: 5065 | K10: -93 | L10: -10750 | M10: -3127 | N10: 7325
B11: Direct taxes | C11: -2240 | D11: -4308 | E11: -4194 | F11: -2040 | G11: -1895 | H11: -3021 | I11: -2659 | J11: -1785 | K11: -2105 | L11: -1910 | M11: -3179 | N11: -4516
B12: Cash from Investing Activity - | C12: -22969 | D12: -27991 | E12: -36232 | F12: -36694 | G12: -39571 | H12: -25139 | I12: -20878 | J12: -33115 | K12: -25672 | L12: -4444 | M12: -15417 | N12: -22782
B13: Fixed assets purchased | C13: -18863 | D13: -26975 | E13: -31962 | F13: -31503 | G13: -16072 | H13: -35079 | I13: -35304 | J13: -29702 | K13: -20205 | L13: -15168 | M13: -19230 | N13: -31414
B14: Fixed assets sold | C14: 37 | D14: 50 | E14: 74 | F14: 59 | G14: 53 | H14: 30 | I14: 67 | J14: 171 | K14: 351 | L14: 230 | M14: 285 | N14: 231
... B33: Net Cash Flow | C33: -2499 | D33: 4277 | E33: 4500 | F33: -2589 | G33: -3167 | H33: 730 | I33: 6843 | J33: -3092 | K33: 13232 | L33: 6459 | M33: -6272 | N33: 8128

Sheet RATIO ANALYSIS 
B1: Ratio Analysis-TATA MOTORS LTD
B2: Years | C2: 42094 | D2: 42460 | E2: 42825 | F2: 43190 | G2: 43555 | H2: 43921 | I2: 44286 | J2: 44651 | K2: 45016 | L2: 45382 | N2: Mean | O2: Median
B3: Sales Growth | C3: 263158.98 | D3: 273045.6 | E3: 269692.51 | F3: 291550.48 | G3: 301938.4 | H3: 261067.97 | I3: 249794.75 | J3: 278453.62 | K3: 345966.97 | L3: 437927.77
B4: Sales Growth | D4: =IFERROR('HISTORICAL FS'!D6,0) -> 0.037569001 | E4: =IFERROR('HISTORICAL FS'!E6,0) -> -0.01228033 | F4: =IFERROR('HISTORICAL FS'!F6,0) -> 0.081047746 | G4: =IFERROR('HISTORICAL FS'!G6,0) -> 0.035629919 | H4: =IFERROR('HISTORICAL FS'!H6,0) -> -0.13536016 | I4: =IFERROR('HISTORICAL FS'!I6,0) -> -0.043181168 | J4: =IFERROR('HISTORICAL FS'!J6,0) -> 0.11472967 | K4: =IFERROR('HISTORICAL FS'!K6,0) -> 0.24245815 | L4: =IFERROR('HISTORICAL FS'!L6,0) -> 0.26580803 | N4: =IFERROR(AVERAGE(D4:L4),0) -> 0.065157874 | O4: =IFERROR(MEDIAN(D4:L4),0) -> 0.037569001
B5: EBITDA Growth | D5: =IFERROR('HISTORICAL FS'!D17/'HISTORICAL FS'!C17-1,0) -> -0.021494114 | E5: =IFERROR('HISTORICAL FS'!E17/'HISTORICAL FS'!D17-1,0) -> -0.22936587 | F5: =IFERROR('HISTORICAL FS'!F17/'HISTORICAL FS'!E17-1,0) -> 0.063165689 | G5: =IFERROR('HISTORICAL FS'!G17/'HISTORICAL FS'!F17-1,0) -> -0.21595203 | H5: =IFERROR('HISTORICAL FS'!H17/'HISTORICAL FS'!G17-1,0) -> -0.27072538 | I5: =IFERROR('HISTORICAL FS'!I17/'HISTORICAL FS'!H17-1,0) -> 0.79503554 | J5: =IFERROR('HISTORICAL FS'!J17/'HISTORICAL FS'!I17-1,0) -> -0.23437418 | K5: =IFERROR('HISTORICAL FS'!K17/'HISTORICAL FS'!J17-1,0) -> 0.28704224 | L5: =IFERROR('HISTORICAL FS'!L17/'HISTORICAL FS'!K17-1,0) -> 0.87134505 | N5: =IFERROR(AVERAGE(D5:L5),0) -> 0.11607522 | O5: =IFERROR(MEDIAN(D5:L5),0) -> -0.021494114
B6: EBIT Growth | D6: =IFERROR('HISTORICAL FS'!D26/'HISTORICAL FS'!C26-1,0) -> -0.34911964 | E6: =IFERROR('HISTORICAL FS'!E26/'HISTORICAL FS'!D26-1,0) -> -0.34058179 | F6: =IFERROR('HISTORICAL FS'!F26/'HISTORICAL FS'!E26-1,0) -> 0.19756108 | G6: =IFERROR('HISTORICAL FS'!G26/'HISTORICAL FS'!F26-1,0) -> -3.8122874 | H6: =IFERROR('HISTORICAL FS'!H26/'HISTORICAL FS'!G26-1,0) -> -0.6627481 | I6: =IFERROR('HISTORICAL FS'!I26/'HISTORICAL FS'!H26-1,0) -> -0.0099905671 | J6: =IFERROR('HISTORICAL FS'!J26/'HISTORICAL FS'!I26-1,0) -> -0.33137075 | K6: =IFERROR('HISTORICAL FS'!K26/'HISTORICAL FS'!J26-1,0) -> -1.4846111 | L6: =IFERROR('HISTORICAL FS'!L26/'HISTORICAL FS'!K26-1,0) -> 7.2367963 | N6: =IFERROR(AVERAGE(D6:L6),0) -> 0.049294231 | O6: =IFERROR(MEDIAN(D6:L6),0) -> -0.34058179
B7: Net Profit Growth | D7: =IFERROR('HISTORICAL FS'!D32/'HISTORICAL FS'!C32-1,0) -> -0.21045545 | E7: =IFERROR('HISTORICAL FS'!E32/'HISTORICAL FS'!D32-1,0) -> -0.45376876 | F7: =IFERROR('HISTORICAL FS'!F32/'HISTORICAL FS'!E32-1,0) -> 0.12361385 | G7: =IFERROR('HISTORICAL FS'!G32/'HISTORICAL FS'!F32-1,0) -> -5.2467746 | H7: =IFERROR('HISTORICAL FS'!H32/'HISTORICAL FS'!G32-1,0) -> -0.62067658 | I7: =IFERROR('HISTORICAL FS'!I32/'HISTORICAL FS'!H32-1,0) -> 0.18595601 | J7: =IFERROR('HISTORICAL FS'!J32/'HISTORICAL FS'!I32-1,0) -> -0.13686392 | K7: =IFERROR('HISTORICAL FS'!K32/'HISTORICAL FS'!J32-1,0) -> -1.2394252 | L7: =IFERROR('HISTORICAL FS'!L32/'HISTORICAL FS'!K32-1,0) -> 10.824642 | N7: =IFERROR(AVERAGE(D7:L7),0) -> 0.35847194 | O7: =IFERROR(MEDIAN(D7:L7),0) -> -0.21045545
B8: Dividend Growth | D8: =IFERROR('HISTORICAL FS'!D39/'HISTORICAL FS'!C39-1,0) -> 0 | E8: =IFERROR('HISTORICAL FS'!E39/'HISTORICAL FS'!D39-1,0) -> -1 | F8: =IFERROR('HISTORICAL FS'!F39/'HISTORICAL FS'!E39-1,0) -> 0 | G8: =IFERROR('HISTORICAL FS'!G39/'HISTORICAL FS'!F39-1,0) -> 0 | H8: =IFERROR('HISTORICAL FS'!H39/'HISTORICAL FS'!G39-1,0) -> 0 | I8: =IFERROR('HISTORICAL FS'!I39/'HISTORICAL FS'!H39-1,0) -> 0 | J8: =IFERROR('HISTORICAL FS'!J39/'HISTORICAL FS'!I39-1,0) -> 0 | K8: =IFERROR('HISTORICAL FS'!K39/'HISTORICAL FS'!J39-1,0) -> 0 | L8: =IFERROR('HISTORICAL FS'!L39/'HISTORICAL FS'!K39-1,0) -> 1.9997122 | N8: =IFERROR(AVERAGE(D8:L8),0) -> 0.11107914 | O8: =IFERROR(MEDIAN(D8:L8),0) -> 0
B10: Gross Margin | C10: =IFERROR('HISTORICAL FS'!C11/'HISTORICAL FS'!C5,0) -> 0.22914703 | D10: =IFERROR('HISTORICAL FS'!D11/'HISTORICAL FS'!D5,0) -> 0.24734524 | E10: =IFERROR('HISTORICAL FS'!E11/'HISTORICAL FS'!E5,0) -> 0.23819078 | F10: =IFERROR('HISTORICAL FS'!F11/'HISTORICAL FS'!F5,0) -> 0.2164999 | G10: =IFERROR('HISTORICAL FS'!G11/'HISTORICAL FS'!G5,0) -> 0.19571167 | H10: =IFERROR('HISTORICAL FS'!H11/'HISTORICAL FS'!H5,0) -> 0.19417127 | I10: =IFERROR('HISTORICAL FS'!I11/'HISTORICAL FS'!I5,0) -> 0.21805386 | J10: =IFERROR('HISTORICAL FS'!J11/'HISTORICAL FS'!J5,0) -> 0.19807108 | ... L10: =IFERROR('HISTORICAL FS'!L11/'HISTORICAL FS'!L5,0) -> 0.23605715 | N10: =IFERROR(AVERAGE(C10:L10),0) -> 0.21800982 | O10: =IFERROR(MEDIAN(C10:L10),0) -> 0.21727688
B11: EBITDA Margin | C11: =IFERROR('HISTORICAL FS'!C18,0) -> 0.14910626 | D11: =IFERROR('HISTORICAL FS'!D18,0) -> 0.14061845 | E11: =IFERROR('HISTORICAL FS'!E18,0) -> 0.10971269 | F11: =IFERROR('HISTORICAL FS'!F18,0) -> 0.10789788 | G11: =IFERROR('HISTORICAL FS'!G18,0) -> 0.081686629 | H11: =IFERROR('HISTORICAL FS'!H18,0) -> 0.068898034 | I11: =IFERROR('HISTORICAL FS'!I18,0) -> 0.12925584 | J11: =IFERROR('HISTORICAL FS'!J18,0) -> 0.088776328 | ... L11: =IFERROR('HISTORICAL FS'!L18,0) -> 0.1359547 | N11: =IFERROR(AVERAGE(C11:L11),0) -> 0.11038688 | O11: =IFERROR(MEDIAN(C11:L11),0) -> 0.10880529
B12: EBIT Margin | C12: =IFERROR((('HISTORICAL FS'!C17-'HISTORICAL FS'!C23)/'HISTORICAL FS'!C5),0) -> 0.098229671 | D12: =IFERROR((('HISTORICAL FS'!D17-'HISTORICAL FS'!D23)/'HISTORICAL FS'!D5),0) -> 0.079417028 | E12: =IFERROR((('HISTORICAL FS'!E17-'HISTORICAL FS'!E23)/'HISTORICAL FS'!E5),0) -> 0.043322301 | F12: =IFERROR((('HISTORICAL FS'!F17-'HISTORICAL FS'!F23)/'HISTORICAL FS'!F5),0) -> 0.033970412 | G12: =IFERROR((('HISTORICAL FS'!G17-'HISTORICAL FS'!G23)/'HISTORICAL FS'!G5),0) -> 0.0035560233 | H12: =IFERROR((('HISTORICAL FS'!H17-'HISTORICAL FS'!H23)/'HISTORICAL FS'!H5),0) -> -0.013170363 | I12: =IFERROR((('HISTORICAL FS'!I17-'HISTORICAL FS'!I23)/'HISTORICAL FS'!I5),0) -> 0.034991608 | J12: =IFERROR((('HISTORICAL FS'!J17-'HISTORICAL FS'!J23)/'HISTORICAL FS'!J5),0) -> -0.00041514993 | ... L12: =IFERROR((('HISTORICAL FS'!L17-'HISTORICAL FS'!L23)/'HISTORICAL FS'!L5),0) -> 0.073683863 | N12: =IFERROR(AVERAGE(C12:L12),0) -> 0.037368974 | O12: =IFERROR(MEDIAN(C12:L12),0) -> 0.03448101
B13: EBT Margin | C13: =IFERROR('HISTORICAL FS'!C27,0) -> 0.082469388 | D13: =IFERROR('HISTORICAL FS'!D27,0) -> 0.051734106 | E13: =IFERROR('HISTORICAL FS'!E27,0) -> 0.034538557 | F13: =IFERROR('HISTORICAL FS'!F27,0) -> 0.038261059 | G13: =IFERROR('HISTORICAL FS'!G27,0) -> -0.10389917 | H13: =IFERROR('HISTORICAL FS'!H27,0) -> -0.040525768 | I13: =IFERROR('HISTORICAL FS'!I27,0) -> -0.041931546 | J13: =IFERROR('HISTORICAL FS'!J27,0) -> -0.025151083 | ... L13: =IFERROR('HISTORICAL FS'!L27,0) -> 0.063834979 | N13: =IFERROR(AVERAGE(C13:L13),0) -> 0.0069140501 | O13: =IFERROR(MEDIAN(C13:L13),0) -> 0.02217427
B14: Net Profit Margin | C14: =IFERROR('HISTORICAL FS'!C33,0) -> 0.05342645 | D14: =IFERROR('HISTORICAL FS'!D33,0) -> 0.040655187 | E14: =IFERROR('HISTORICAL FS'!E33,0) -> 0.022483235 | F14: =IFERROR('HISTORICAL FS'!F33,0) -> 0.023368509 | G14: =IFERROR('HISTORICAL FS'!G33,0) -> -0.0958265 | H14: =IFERROR('HISTORICAL FS'!H33,0) -> -0.042039742 | I14: =IFERROR('HISTORICAL FS'!I33,0) -> -0.05210734 | J14: =IFERROR('HISTORICAL FS'!J33,0) -> -0.040346755 | ... L14: =IFERROR('HISTORICAL FS'!L33,0) -> 0.072630128 | N14: =IFERROR(AVERAGE(C14:L14),0) -> -0.00099818949 | O14: =IFERROR(MEDIAN(C14:L14),0) -> 0.015129084
B16: Sales Expenses % Sales | C16: =IFERROR('HISTORICAL FS'!C15,0) -> 0.08004078 | D16: =IFERROR('HISTORICAL FS'!D15,0) -> 0.10672679 | E16: =IFERROR('HISTORICAL FS'!E15,0) -> 0.1284781 | F16: =IFERROR('HISTORICAL FS'!F15,0) -> 0.10860202 | G16: =IFERROR('HISTORICAL FS'!G15,0) -> 0.11402505 | H16: =IFERROR('HISTORICAL FS'!H15,0) -> 0.12527324 | I16: =IFERROR('HISTORICAL FS'!I15,0) -> 0.088798023 | J16: =IFERROR('HISTORICAL FS'!J15,0) -> 0.10929475 | ... L16: =IFERROR('HISTORICAL FS'!L15,0) -> 0.10010244 | N16: =IFERROR(AVERAGE(C16:L16),0) -> 0.10762294 | O16: =IFERROR(MEDIAN(C16:L16),0) -> 0.10894839
B17: Depriciation % Sales | C17: =IFERROR('HISTORICAL FS'!C24,0) -> 0.050876584 | D17: =IFERROR('HISTORICAL FS'!D24,0) -> 0.061201426 | E17: =IFERROR('HISTORICAL FS'!E24,0) -> 0.066390387 | F17: =IFERROR('HISTORICAL FS'!F24,0) -> 0.073927472 | G17: =IFERROR('HISTORICAL FS'!G24,0) -> 0.078130605 | H17: =IFERROR('HISTORICAL FS'!H24,0) -> 0.082068398 | I17: =IFERROR('HISTORICAL FS'!I24,0) -> 0.094264231 | J17: =IFERROR('HISTORICAL FS'!J24,0) -> 0.089191478 | ... L17: =IFERROR('HISTORICAL FS'!L24,0) -> 0.06227084 | N17: =IFERROR(AVERAGE(C17:L17),0) -> 0.073017903 | O17: =IFERROR(MEDIAN(C17:L17),0) -> 0.072892542
B18: Operating Income % Sales | C18: =IFERROR(C12,0) -> 0.098229671 | D18: =IFERROR(D12,0) -> 0.079417028 | E18: =IFERROR(E12,0) -> 0.043322301 | F18: =IFERROR(F12,0) -> 0.033970412 | G18: =IFERROR(G12,0) -> 0.0035560233 | H18: =IFERROR(H12,0) -> -0.013170363 | I18: =IFERROR(I12,0) -> 0.034991608 | J18: =IFERROR(J12,0) -> -0.00041514993 | ... L18: =IFERROR(L12,0) -> 0.073683863 | N18: =IFERROR(AVERAGE(C18:L18),0) -> 0.037368974 | O18: =IFERROR(MEDIAN(C18:L18),0) -> 0.03448101
B20: Return on Capital Employed | C20: =IFERROR(('HISTORICAL FS'!C17-'HISTORICAL FS'!C23)/('HISTORICAL FS'!C46+'HISTORICAL FS'!C47+'HISTORICAL FS'!C48),0) -> 0.19904181 | D20: =IFERROR(('HISTORICAL FS'!D17-'HISTORICAL FS'!D23)/('HISTORICAL FS'!D46+'HISTORICAL FS'!D47+'HISTORICAL FS'!D48),0) -> 0.1462081 | E20: =IFERROR(('HISTORICAL FS'!E17-'HISTORICAL FS'!E23)/('HISTORICAL FS'!E46+'HISTORICAL FS'!E47+'HISTORICAL FS'!E48),0) -> 0.085490986 | F20: =IFERROR(('HISTORICAL FS'!F17-'HISTORICAL FS'!F23)/('HISTORICAL FS'!F46+'HISTORICAL FS'!F47+'HISTORICAL FS'!F48),0) -> 0.053716114 | G20: =IFERROR(('HISTORICAL FS'!G17-'HISTORICAL FS'!G23)/('HISTORICAL FS'!G46+'HISTORICAL FS'!G47+'HISTORICAL FS'!G48),0) -> 0.0064542734 | H20: =IFERROR(('HISTORICAL FS'!H17-'HISTORICAL FS'!H23)/('HISTORICAL FS'!H46+'HISTORICAL FS'!H47+'HISTORICAL FS'!H48),0) -> -0.018302178 | I20: =IFERROR(('HISTORICAL FS'!I17-'HISTORICAL FS'!I23)/('HISTORICAL FS'!I46+'HISTORICAL FS'!I47+'HISTORICAL FS'!I48),0) -> 0.044284325 | J20: =IFERROR(('HISTORICAL FS'!J17-'HISTORICAL FS'!J23)/('HISTORICAL FS'!J46+'HISTORICAL FS'!J47+'HISTORICAL FS'!J48),0) -> -0.00060520306 | ... L20: =IFERROR(('HISTORICAL FS'!L17-'HISTORICAL FS'!L23)/('HISTORICAL FS'!L46+'HISTORICAL FS'!L47+'HISTORICAL FS'!L48),0) -> 0.16790573 | N20: =IFERROR(AVERAGE(C20:L20),0) -> 0.072295691 | O20: =IFERROR(MEDIAN(C20:L20),0) -> 0.049000219
B21: Retained Earning % | C21: =IFERROR('HISTORICAL FS'!C43,0) -> 1 | D21: =IFERROR('HISTORICAL FS'!D43,0) -> 0.99388148 | E21: =IFERROR('HISTORICAL FS'!E43,0) -> 1 | F21: =IFERROR('HISTORICAL FS'!F43,0) -> 1 | G21: =IFERROR('HISTORICAL FS'!G43,0) -> 0 | H21: =IFERROR('HISTORICAL FS'!H43,0) -> 0 | I21: =IFERROR('HISTORICAL FS'!I43,0) -> 0 | J21: =IFERROR('HISTORICAL FS'!J43,0) -> 0 | ... L21: =IFERROR('HISTORICAL FS'!L43,0) -> 0.92770403 | N21: =IFERROR(AVERAGE(C21:L21),0) -> 0.56368059 | O21: =IFERROR(MEDIAN(C21:L21),0) -> 0.82146223
B22: Return on Equity % | C22: =IFERROR('HISTORICAL FS'!C32/SUM('HISTORICAL FS'!C46:C47),0) -> 0.24989638 | D22: =IFERROR('HISTORICAL FS'!D32/SUM('HISTORICAL FS'!D46:D47),0) -> 0.14060014 | E22: =IFERROR('HISTORICAL FS'!E32/SUM('HISTORICAL FS'!E46:E47),0) -> 0.1044327 | F22: =IFERROR('HISTORICAL FS'!F32/SUM('HISTORICAL FS'!F46:F47),0) -> 0.071395255 | G22: =IFERROR('HISTORICAL FS'!G32/SUM('HISTORICAL FS'!G46:G47),0) -> -0.48078949 | H22: =IFERROR('HISTORICAL FS'!H32/SUM('HISTORICAL FS'!H46:H47),0) -> -0.17399312 | I22: =IFERROR('HISTORICAL FS'!I32/SUM('HISTORICAL FS'!I46:I47),0) -> -0.23560023 | J22: =IFERROR('HISTORICAL FS'!J32/SUM('HISTORICAL FS'!J46:J47),0) -> -0.25211821 | ... L22: =IFERROR('HISTORICAL FS'!L32/SUM('HISTORICAL FS'!L46:L47),0) -> 0.37455831 | N22: =IFERROR(AVERAGE(C22:L22),0) -> -0.014226778 | O22: =IFERROR(MEDIAN(C22:L22),0) -> 0.065372868
B23: Self Sustained Growth Rate | C23: =IFERROR(C21*C22,0) -> 0.24989638 | D23: =IFERROR(D21*D22,0) -> 0.13973988 | E23: =IFERROR(E21*E22,0) -> 0.1044327 | F23: =IFERROR(F21*F22,0) -> 0.071395255 | G23: =IFERROR(G21*G22,0) -> 0 | H23: =IFERROR(H21*H22,0) -> 0 | I23: =IFERROR(I21*I22,0) -> 0 | J23: =IFERROR(J21*J22,0) -> 0 | ... L23: =IFERROR(L21*L22,0) -> 0.34747925 | N23: =IFERROR(AVERAGE(C23:L23),0) -> 0.095539214 | O23: =IFERROR(MEDIAN(C23:L23),0) -> 0.056921966
B24: Interest Coverage Ratio | C24: =IFERROR(('HISTORICAL FS'!C17-'HISTORICAL FS'!C23)/'HISTORICAL FS'!C20,0) -> 5.317304 | D24: =IFERROR(('HISTORICAL FS'!D17-'HISTORICAL FS'!D23)/'HISTORICAL FS'!D20,0) -> 4.4352864 | E24: =IFERROR(('HISTORICAL FS'!E17-'HISTORICAL FS'!E23)/'HISTORICAL FS'!E20,0) -> 2.7568835 | F24: =IFERROR(('HISTORICAL FS'!F17-'HISTORICAL FS'!F23)/'HISTORICAL FS'!F20,0) -> 2.1154494 | G24: =IFERROR(('HISTORICAL FS'!G17-'HISTORICAL FS'!G23)/'HISTORICAL FS'!G20,0) -> 0.18645157 | H24: =IFERROR(('HISTORICAL FS'!H17-'HISTORICAL FS'!H23)/'HISTORICAL FS'!H20,0) -> -0.47469327 | I24: =IFERROR(('HISTORICAL FS'!I17-'HISTORICAL FS'!I23)/'HISTORICAL FS'!I20,0) -> 1.0794784 | J24: =IFERROR(('HISTORICAL FS'!J17-'HISTORICAL FS'!J23)/'HISTORICAL FS'!J20,0) -> -0.012414276 | ... L24: =IFERROR(('HISTORICAL FS'!L17-'HISTORICAL FS'!L23)/'HISTORICAL FS'!L20,0) -> 3.2314225 | N24: =IFERROR(AVERAGE(C24:L24),0) -> 1.9315375 | O24: =IFERROR(MEDIAN(C24:L24),0) -> 1.5974639
B26: Debtor Turnover Ratio | C26: =IFERROR('HISTORICAL FS'!C5/'HISTORICAL FS'!C58,0) -> 20.920168 | D26: =IFERROR('HISTORICAL FS'!D5/'HISTORICAL FS'!D58,0) -> 20.119918 | E26: =IFERROR('HISTORICAL FS'!E5/'HISTORICAL FS'!E58,0) -> 19.160353 | F26: =IFERROR('HISTORICAL FS'!F5/'HISTORICAL FS'!F58,0) -> 14.655712 | G26: =IFERROR('HISTORICAL FS'!G5/'HISTORICAL FS'!G58,0) -> 15.894699 | H26: =IFERROR('HISTORICAL FS'!H5/'HISTORICAL FS'!H58,0) -> 23.366617 | I26: =IFERROR('HISTORICAL FS'!I5/'HISTORICAL FS'!I58,0) -> 19.701331 | J26: =IFERROR('HISTORICAL FS'!J5/'HISTORICAL FS'!J58,0) -> 22.379918 | ... L26: =IFERROR('HISTORICAL FS'!L5/'HISTORICAL FS'!L58,0) -> 25.833688 | N26: =IFERROR(AVERAGE(C26:L26),0) -> 20.401535 | O26: =IFERROR(MEDIAN(C26:L26),0) -> 20.520043
B27: Creditor Turnover Ratio | C27: =IFERROR('HISTORICAL FS'!C5/'HISTORICAL FS'!C49,0) -> 2.4493011 | D27: =IFERROR('HISTORICAL FS'!D5/'HISTORICAL FS'!D49,0) -> 2.3769604 | E27: =IFERROR('HISTORICAL FS'!E5/'HISTORICAL FS'!E49,0) -> 1.9842808 | F27: =IFERROR('HISTORICAL FS'!F5/'HISTORICAL FS'!F49,0) -> 2.041478 | G27: =IFERROR('HISTORICAL FS'!G5/'HISTORICAL FS'!G49,0) -> 2.1667848 | H27: =IFERROR('HISTORICAL FS'!H5/'HISTORICAL FS'!H49,0) -> 1.9731057 | I27: =IFERROR('HISTORICAL FS'!I5/'HISTORICAL FS'!I49,0) -> 1.7323685 | J27: =IFERROR('HISTORICAL FS'!J5/'HISTORICAL FS'!J49,0) -> 2.0170312 | ... L27: =IFERROR('HISTORICAL FS'!L5/'HISTORICAL FS'!L49,0) -> 2.4694234 | N27: =IFERROR(AVERAGE(C27:L27),0) -> 2.143934 | O27: =IFERROR(MEDIAN(C27:L27),0) -> 2.1041314
B28: Inventory Turnover Ratio | C28: =IFERROR('HISTORICAL FS'!C5/'HISTORICAL FS'!C59,0) -> 8.990022 | D28: =IFERROR('HISTORICAL FS'!D5/'HISTORICAL FS'!D59,0) -> 8.3613381 | E28: =IFERROR('HISTORICAL FS'!E5/'HISTORICAL FS'!E59,0) -> 7.6867643 | F28: =IFERROR('HISTORICAL FS'!F5/'HISTORICAL FS'!F59,0) -> 6.9190052 | G28: =IFERROR('HISTORICAL FS'!G5/'HISTORICAL FS'!G59,0) -> 7.7392856 | H28: =IFERROR('HISTORICAL FS'!H5/'HISTORICAL FS'!H59,0) -> 6.9698269 | I28: =IFERROR('HISTORICAL FS'!I5/'HISTORICAL FS'!I59,0) -> 6.9217099 | J28: =IFERROR('HISTORICAL FS'!J5/'HISTORICAL FS'!J59,0) -> 7.9015588 | ... L28: =IFERROR('HISTORICAL FS'!L5/'HISTORICAL FS'!L59,0) -> 9.1639138 | N28: =IFERROR(AVERAGE(C28:L28),0) -> 7.9142289 | O28: =IFERROR(MEDIAN(C28:L28),0) -> 7.8204222
B29: Fixed Asset Turnover | C29: =IFERROR('HISTORICAL FS'!C5/'HISTORICAL FS'!C52,0) -> 2.9742371 | D29: =IFERROR('HISTORICAL FS'!D5/'HISTORICAL FS'!D52,0) -> 2.5463128 | E29: =IFERROR('HISTORICAL FS'!E5/'HISTORICAL FS'!E52,0) -> 2.8109343 | F29: =IFERROR('HISTORICAL FS'!F5/'HISTORICAL FS'!F52,0) -> 2.4012949 | G29: =IFERROR('HISTORICAL FS'!G5/'HISTORICAL FS'!G52,0) -> 2.714432 | H29: =IFERROR('HISTORICAL FS'!H5/'HISTORICAL FS'!H52,0) -> 2.0539206 | I29: =IFERROR('HISTORICAL FS'!I5/'HISTORICAL FS'!I52,0) -> 1.8008727 | J29: =IFERROR('HISTORICAL FS'!J5/'HISTORICAL FS'!J52,0) -> 2.0053489 | ... L29: =IFERROR('HISTORICAL FS'!L5/'HISTORICAL FS'!L52,0) -> 3.6107195 | N29: =IFERROR(AVERAGE(C29:L29),0) -> 2.5537452 | O29: =IFERROR(MEDIAN(C29:L29),0) -> 2.582846
B30: Capital Turnover | C30: =IFERROR('HISTORICAL FS'!C5/SUM('HISTORICAL FS'!C46:C47),0) -> 4.6773907 | D30: =IFERROR('HISTORICAL FS'!D5/SUM('HISTORICAL FS'!D46:D47),0) -> 3.4583567 | E30: =IFERROR('HISTORICAL FS'!E5/SUM('HISTORICAL FS'!E46:E47),0) -> 4.6449144 | F30: =IFERROR('HISTORICAL FS'!F5/SUM('HISTORICAL FS'!F46:F47),0) -> 3.0551909 | G30: =IFERROR('HISTORICAL FS'!G5/SUM('HISTORICAL FS'!G46:G47),0) -> 5.0172916 | H30: =IFERROR('HISTORICAL FS'!H5/SUM('HISTORICAL FS'!H46:H47),0) -> 4.138777 | I30: =IFERROR('HISTORICAL FS'!I5/SUM('HISTORICAL FS'!I46:I47),0) -> 4.5214404 | J30: =IFERROR('HISTORICAL FS'!J5/SUM('HISTORICAL FS'!J46:J47),0) -> 6.2487853 | ... L30: =IFERROR('HISTORICAL FS'!L5/SUM('HISTORICAL FS'!L46:L47),0) -> 5.1570652 | N30: =IFERROR(AVERAGE(C30:L30),0) -> 4.855278 | O30: =IFERROR(MEDIAN(C30:L30),0) -> 4.6611525
B32: Debtor Days | C32: =IFERROR(365/C26,0) -> 17.447278 | D32: =IFERROR(365/D26,0) -> 18.141227 | E32: =IFERROR(365/E26,0) -> 19.049753 | F32: =IFERROR(365/F26,0) -> 24.904965 | G32: =IFERROR(365/G26,0) -> 22.963631 | H32: =IFERROR(365/H26,0) -> 15.620575 | I32: =IFERROR(365/I26,0) -> 18.526667 | J32: =IFERROR(365/J26,0) -> 16.309265 | ... L32: =IFERROR(365/L26,0) -> 14.128838 | N32: =IFERROR(AVERAGE(C32:L32),0) -> 18.369598 | O32: =IFERROR(MEDIAN(C32:L32),0) -> 17.794253
B33: Payable Days | C33: =IFERROR(365/C27,0) -> 149.02211 | D33: =IFERROR(365/D27,0) -> 153.55746 | E33: =IFERROR(365/E27,0) -> 183.94574 | F33: =IFERROR(365/F27,0) -> 178.79203 | G33: =IFERROR(365/G27,0) -> 168.45236 | H33: =IFERROR(365/H27,0) -> 184.98755 | I33: =IFERROR(365/I27,0) -> 210.69421 | J33: =IFERROR(365/J27,0) -> 180.95902 | ... L33: =IFERROR(365/L27,0) -> 147.80778 | N33: =IFERROR(AVERAGE(C33:L33),0) -> 172.19978 | O33: =IFERROR(MEDIAN(C33:L33),0) -> 173.62219
B34: Inventory Days | C34: =IFERROR(365/C28,0) -> 40.600568 | D34: =IFERROR(365/D28,0) -> 43.6533 | E34: =IFERROR(365/E28,0) -> 47.484219 | F34: =IFERROR(365/F28,0) -> 52.753249 | G34: =IFERROR(365/G28,0) -> 47.161976 | H34: =IFERROR(365/H28,0) -> 52.368589 | I34: =IFERROR(365/I28,0) -> 52.732635 | J34: =IFERROR(365/J28,0) -> 46.193417 | ... L34: =IFERROR(365/L28,0) -> 39.830143 | N34: =IFERROR(AVERAGE(C34:L34),0) -> 46.57756 | O34: =IFERROR(MEDIAN(C34:L34),0) -> 46.677696
B35: Cash Conversion Cycle | C35: =SUM(C32,C34)-C33 -> -90.974259 | D35: =SUM(D32,D34)-D33 -> -91.762933 | E35: =SUM(E32,E34)-E33 -> -117.41177 | F35: =SUM(F32,F34)-F33 -> -101.13382 | G35: =SUM(G32,G34)-G33 -> -98.326751 | H35: =SUM(H32,H34)-H33 -> -116.99839 | I35: =SUM(I32,I34)-I33 -> -139.4349 | J35: =SUM(J32,J34)-J33 -> -118.45634 | ... L35: =SUM(L32,L34)-L33 -> -93.848801 | N35: =IFERROR(AVERAGE(C35:L35),0) -> -107.25262 | O35: =IFERROR(MEDIAN(C35:L35),0) -> -102.65603
B37: CFO/SALES | C37: =IFERROR('HISTORICAL FS'!C78/'HISTORICAL FS'!C5,0) -> 0.13502104 | D37: =IFERROR('HISTORICAL FS'!D78/'HISTORICAL FS'!D5,0) -> 0.13880099 | E37: =IFERROR('HISTORICAL FS'!E78/'HISTORICAL FS'!E5,0) -> 0.11197938 | F37: =IFERROR('HISTORICAL FS'!F78/'HISTORICAL FS'!F5,0) -> 0.081828025 | G37: =IFERROR('HISTORICAL FS'!G78/'HISTORICAL FS'!G5,0) -> 0.062569054 | H37: =IFERROR('HISTORICAL FS'!H78/'HISTORICAL FS'!H5,0) -> 0.10201558 | I37: =IFERROR('HISTORICAL FS'!I78/'HISTORICAL FS'!I5,0) -> 0.11609531 | J37: =IFERROR('HISTORICAL FS'!J78/'HISTORICAL FS'!J5,0) -> 0.051290409 | ... L37: =IFERROR('HISTORICAL FS'!L78/'HISTORICAL FS'!L5,0) -> 0.15508494 | N37: =IFERROR(AVERAGE(C37:L37),0) -> 0.1056972 | O37: =IFERROR(MEDIAN(C37:L37),0) -> 0.1071333
B38: CFO/TOTAL ASSETS | C38: =IFERROR('HISTORICAL FS'!C78/'HISTORICAL FS'!C63,0) -> 0.14972518 | D38: =IFERROR('HISTORICAL FS'!D78/'HISTORICAL FS'!D63,0) -> 0.14400185 | E38: =IFERROR('HISTORICAL FS'!E78/'HISTORICAL FS'!E63,0) -> 0.11079302 | F38: =IFERROR('HISTORICAL FS'!F78/'HISTORICAL FS'!F63,0) -> 0.072914417 | G38: =IFERROR('HISTORICAL FS'!G78/'HISTORICAL FS'!G63,0) -> 0.061798444 | H38: =IFERROR('HISTORICAL FS'!H78/'HISTORICAL FS'!H63,0) -> 0.083181494 | I38: =IFERROR('HISTORICAL FS'!I78/'HISTORICAL FS'!I63,0) -> 0.084902092 | J38: =IFERROR('HISTORICAL FS'!J78/'HISTORICAL FS'!J63,0) -> 0.043402222 | ... L38: =IFERROR('HISTORICAL FS'!L78/'HISTORICAL FS'!L63,0) -> 0.18379489 | N38: =IFERROR(AVERAGE(C38:L38),0) -> 0.10402522 | O38: =IFERROR(MEDIAN(C38:L38),0) -> 0.095320338
B39: CFO/TOTAL DEBT | C39: =IFERROR('HISTORICAL FS'!C78/'HISTORICAL FS'!C48,0) -> 0.4827036 | D39: =IFERROR('HISTORICAL FS'!D78/'HISTORICAL FS'!D48,0) -> 0.54641035 | E39: =IFERROR('HISTORICAL FS'!E78/'HISTORICAL FS'!E48,0) -> 0.38420446 | F39: =IFERROR('HISTORICAL FS'!F78/'HISTORICAL FS'!F48,0) -> 0.26820544 | G39: =IFERROR('HISTORICAL FS'!G78/'HISTORICAL FS'!G48,0) -> 0.17793209 | H39: =IFERROR('HISTORICAL FS'!H78/'HISTORICAL FS'!H48,0) -> 0.21342659 | I39: =IFERROR('HISTORICAL FS'!I78/'HISTORICAL FS'!I48,0) -> 0.20403774 | J39: =IFERROR('HISTORICAL FS'!J78/'HISTORICAL FS'!J48,0) -> 0.097521984 | ... L39: =IFERROR('HISTORICAL FS'!L78/'HISTORICAL FS'!L48,0) -> 0.63317562 | N39: =IFERROR(AVERAGE(C39:L39),0) -> 0.3271484 | O39: =IFERROR(MEDIAN(C39:L39),0) -> 0.26603581

Sheet STATEMENTS
D3: 2020 | E3: 2021 | F3: 2022 | G3: 2023 | H3: 2024 | I3: 2025 | J3: 2026
B4: TATA STEELS
B5: INR(CRORES) | D5: 2020 | E5: 2021 | F5: 2022 | G5: 2023 | H5: 2024 | I5: 2025 | J5: 2026
B7: ="Income Statement"&"-" & B4 -> Income Statement-TATA STEELS
B8: Revenue | D8: 20000 | E8: 22500 | F8: =E8*(1+F23) -> 24750 | G8: =F8*(1+G23) -> 27225 | H8: =G8*(1+H23) -> 31308.75 | I8: =H8*(1+I23) -> 36005.063 | J8: =I8*(1+J23) -> 41405.822
B9: COGS | D9: 8000 | E9: 9000 | F9: =F8*F24 -> 9900 | G9: =G8*G24 -> 10890 | H9: =H8*H24 -> 12523.5 | I9: =I8*I24 -> 14402.025 | J9: =J8*J24 -> 16562.329
B10: Gross Profit | D10: =D8-D9 -> 12000 | E10: 13500 | F10: =F8-F9 -> 14850 | G10: =G8-G9 -> 16335 | H10: =H8-H9 -> 18785.25 | I10: =I8-I9 -> 21603.038 | J10: =J8-J9 -> 24843.493
B11: Selling and G. Expenses | D11: 2000 | E11: 2250 | F11: =F25 -> 2500 | G11: =F11 -> 2500 | H11: =G11 -> 2500 | I11: =H11 -> 2500 | J11: =I11 -> 2500
B12: EBITDA | D12: =D10-D11 -> 10000 | E12: 11250 | F12: =F10-F11 -> 12350 | G12: =G10-G11 -> 13835 | H12: =H10-H11 -> 16285.25 | I12: =I10-I11 -> 19103.038 | J12: =J10-J11 -> 22343.493
B13: Depriciation | D13: 800 | E13: 900 | F13: =F8*F26 -> 1237.5 | G13: =G8*G26 -> 1361.25 | H13: =H8*H26 -> 1565.4375 | I13: =I8*I26 -> 1800.2531 | J13: =J8*J26 -> 2070.2911
B14: Interest | D14: 200 | E14: 225 | F14: =F27 -> 250 | G14: =F14 -> 250 | H14: =G14 -> 250 | I14: =H14 -> 250 | J14: =I14 -> 250
B15: EBT | D15: =D12-SUM(D13:D14) -> 9000 | E15: 10125 | F15: =F12-SUM(F13:F14) -> 10862.5 | G15: =G12-SUM(G13:G14) -> 12223.75 | H15: =H12-SUM(H13:H14) -> 14469.813 | I15: =I12-SUM(I13:I14) -> 17052.784 | J15: =J12-SUM(J13:J14) -> 20023.202
B16: Taxes | D16: 2700 | E16: 3038 | F16: =F15*F28 -> 3258.75 | G16: =G15*G28 -> 3667.125 | H16: =H15*H28 -> 4340.9438 | I16: =I15*I28 -> 5115.8353 | J16: =J15*J28 -> 6006.9606
B17: Net Income | D17: =D15-D16 -> 6300 | E17: 7088 | F17: =F15-F16 -> 7603.75 | G17: =G15-G16 -> 8556.625 | H17: =H15-H16 -> 10128.869 | I17: =I15-I16 -> 11936.949 | J17: =J15-J16 -> 14016.241
B22: ="Assumption Drivers"&"-"&B4 -> Assumption Drivers-TATA STEELS
B23: Revenue Growth | D23: NA | E23: =E8/D8-1 -> 0.125 | F23: 0.1 | G23: =F23 -> 0.1 | H23: 0.15 | I23: =H23 -> 0.15 | J23: =I23 -> 0.15
B24: COGS % of R | D24: =D9/D8 -> 0.4 | E24: =E9/E8 -> 0.4 | F24: 0.4 | G24: =F24 -> 0.4 | H24: =G24 -> 0.4 | I24: =H24 -> 0.4 | J24: =I24 -> 0.4
B25: S & G Expenses | D25: 2000 | E25: 2250 | F25: 2500 | G25: =F25 -> 2500 | H25: =G25 -> 2500 | I25: =H25 -> 2500 | J25: =I25 -> 2500
B26: Depriciation % Sales | D26: =D13/D8 -> 0.04 | E26: =E13/E8 -> 0.04 | F26: 0.05 | G26: =F26 -> 0.05 | H26: =G26 -> 0.05 | I26: =H26 -> 0.05 | J26: =I26 -> 0.05
B27: Interest | D27: 200 | E27: 225 | F27: 250 | G27: 250 | H27: 250 | I27: 250 | J27: 250
B28: Taxes | D28: 0.3 | E28: 0.3 | F28: 0.3 | G28: =F28 -> 0.3 | H28: =G28 -> 0.3 | I28: =H28 -> 0.3 | J28: =I28 -> 0.3
B33: ="Common Size Statement"&"-"&B4 -> Common Size Statement-TATA STEELS
B34: Revenue | D34: 1 | E34: =E8/E$9 -> 2.5 | F34: =F8/F$9 -> 2.5 | G34: =G8/G$9 -> 2.5 | H34: =H8/H$9 -> 2.5 | I34: =I8/I$9 -> 2.5 | J34: =J8/J$9 -> 2.5
B35: COGS | D35: 0.4 | E35: =E9/E$9 -> 1 | F35: =F9/F$9 -> 1 | G35: =G9/G$9 -> 1 | H35: =H9/H$9 -> 1 | I35: =I9/I$9 -> 1 | J35: =J9/J$9 -> 1
B36: Gross Profit | D36: =D10/D$9 -> 1.5 | E36: =E10/E$9 -> 1.5 | F36: =F10/F$9 -> 1.5 | G36: =G10/G$9 -> 1.5 | H36: =H10/H$9 -> 1.5 | I36: =I10/I$9 -> 1.5 | J36: =J10/J$9 -> 1.5
B37: Selling and G. Expenses | D37: =D11/D$9 -> 0.25 | E37: =E11/E$9 -> 0.25 | F37: =F11/F$9 -> 0.25252525 | G37: =G11/G$9 -> 0.22956841 | H37: =H11/H$9 -> 0.19962471 | I37: =I11/I$9 -> 0.1735867 | J37: =J11/J$9 -> 0.15094496
B38: EBITDA | D38: =D12/D$9 -> 1.25 | E38: =E12/E$9 -> 1.25 | F38: =F12/F$9 -> 1.2474747 | G38: =G12/G$9 -> 1.2704316 | H38: =H12/H$9 -> 1.3003753 | I38: =I12/I$9 -> 1.3264133 | J38: =J12/J$9 -> 1.349055
B39: Depriciation | D39: =D13/D$9 -> 0.1 | E39: =E13/E$9 -> 0.1 | F39: =F13/F$9 -> 0.125 | G39: =G13/G$9 -> 0.125 | H39: =H13/H$9 -> 0.125 | I39: =I13/I$9 -> 0.125 | J39: =J13/J$9 -> 0.125
B40: Interest | D40: =D14/D$9 -> 0.025 | E40: =E14/E$9 -> 0.025 | F40: =F14/F$9 -> 0.025252525 | G40: =G14/G$9 -> 0.022956841 | H40: =H14/H$9 -> 0.019962471 | I40: =I14/I$9 -> 0.01735867 | J40: =J14/J$9 -> 0.015094496
B41: EBT | D41: =D15/D$9 -> 1.125 | E41: =E15/E$9 -> 1.125 | F41: =F15/F$9 -> 1.0972222 | G41: =G15/G$9 -> 1.1224747 | H41: =H15/H$9 -> 1.1554128 | I41: =I15/I$9 -> 1.1840546 | J41: =J15/J$9 -> 1.2089605
B42: Taxes | D42: =D16/D$9 -> 0.3375 | E42: =E16/E$9 -> 0.33755556 | F42: =F16/F$9 -> 0.32916667 | G42: =G16/G$9 -> 0.33674242 | H42: =H16/H$9 -> 0.34662385 | I42: =I16/I$9 -> 0.35521639 | J42: =J16/J$9 -> 0.36268816
B43: Net Income | D43: =D17/D$9 -> 0.7875 | E43: =E17/E$9 -> 0.78755556 | F43: =F17/F$9 -> 0.76805556 | G43: =G17/G$9 -> 0.78573232 | H43: =H17/H$9 -> 0.80878898 | I43: =I17/I$9 -> 0.82883824 | J43: =J17/J$9 -> 0.84627238
B46: ="Change Analysis Statement"&"-"&B4 -> Change Analysis Statement-TATA STEELS
C47: 0.1
B48: Revenue | D48: =D8*(1+$C$48) -> 20000 | E48: =E8*(1+$C$48) -> 22500 | F48: =F8*(1+$C$48) -> 24750 | G48: =G8*(1+$C$48) -> 27225 | H48: =H8*(1+$C$48) -> 31308.75 | I48: =I8*(1+$C$48) -> 36005.063 | J48: =J8*(1+$C$48) -> 41405.822
B49: COGS | D49: =D9*(1+$C$48) -> 8000 | E49: =E9*(1+$C$48) -> 9000 | F49: =F9*(1+$C$48) -> 9900 | G49: =G9*(1+$C$48) -> 10890 | H49: =H9*(1+$C$48) -> 12523.5 | I49: =I9*(1+$C$48) -> 14402.025 | J49: =J9*(1+$C$48) -> 16562.329
B50: Gross Profit | D50: =D10*(1+$C$48) -> 12000 | E50: =E10*(1+$C$48) -> 13500 | F50: =F10*(1+$C$48) -> 14850 | G50: =G10*(1+$C$48) -> 16335 | H50: =H10*(1+$C$48) -> 18785.25 | I50: =I10*(1+$C$48) -> 21603.038 | J50: =J10*(1+$C$48) -> 24843.493
B51: Selling Expenses | D51: =D11*(1+$C$48) -> 2000 | E51: =E11*(1+$C$48) -> 2250 | F51: =F11*(1+$C$48) -> 2500 | G51: =G11*(1+$C$48) -> 2500 | H51: =H11*(1+$C$48) -> 2500 | I51: =I11*(1+$C$48) -> 2500 | J51: =J11*(1+$C$48) -> 2500
B52: EBITDA | D52: =D12*(1+$C$48) -> 10000 | E52: =E12*(1+$C$48) -> 11250 | F52: =F12*(1+$C$48) -> 12350 | G52: =G12*(1+$C$48) -> 13835 | H52: =H12*(1+$C$48) -> 16285.25 | I52: =I12*(1+$C$48) -> 19103.038 | J52: =J12*(1+$C$48) -> 22343.493
B53: Depriciation | D53: =D13*(1+$C$48) -> 800 | E53: =E13*(1+$C$48) -> 900 | F53: =F13*(1+$C$48) -> 1237.5 | G53: =G13*(1+$C$48) -> 1361.25 | H53: =H13*(1+$C$48) -> 1565.4375 | I53: =I13*(1+$C$48) -> 1800.2531 | J53: =J13*(1+$C$48) -> 2070.2911
...

Sheet RAW DATA
A1: INCOME STATEMENT | C1: 2020 | D1: 2021 | F1: 2022 | G1: 2023 | H1: 2024
A2: Revenue | C2: 20000 | D2: 22500
A3: COGS | C3: 8000 | D3: 9000
A4: Gross Profit | C4: =(C2-C3) -> 12000 | D4: 13500
A5: Selling and General Expenses | C5: 2000 | D5: 2250
A6: EBITDA | C6: 10000 | D6: 11250
A7: Depriciation | C7: 800 | D7: 900
A8: Interest | C8: 200 | D8: 225
A9: EBT | C9: 9000 | D9: 10125
A10: Taxes | C10: 2700 | D10: 3038
A11: Net Income | C11: 6300 | D11: 7088

Sheet PEER COMPARISON
B2: Peer Comp
H4: Debt/ | I4: Debt/ | J4: Levered | K4: Unlevered
E5: Total Debt | F5: Total Equity | G5: Tax Rate 1 | H5: Equity | I5: Capital | J5: Beta 2 | K5: Beta 3
B6: Avenue Super. | D6: India | E6: =[1]Sheet1!P2 -> 712.91 | F6: =[1]Sheet1!N2 -> 281370.49 | G6: 0.3 | H6: =E6/F6 -> 0.0025337056 | I6: =E6/SUM(E6:F6) -> 0.0025273022 | J6: =[2]Sheet1!$P$7 -> 1.0622811 | K6: =J6/(1+(1-G6)*H6) -> 1.0604004
B7: Trent | D7: India | E7: =[1]Sheet1!P3 -> 1842.2 | F7: =[1]Sheet1!N3 -> 185816.8 | G7: 0.3 | H7: =E7/F7 -> 0.0099140659 | I7: =E7/SUM(E7:F7) -> 0.0098167421 | J7: 1.11 | K7: =J7/(1+(1-G7)*H7) -> 1.1023499
B8: Aditya Bir. Fas. | D8: India | E8: =[1]Sheet1!P4 -> 9999.18 | F8: =[1]Sheet1!N4 -> 33165.94 | G8: 0.3 | H8: =E8/F8 -> 0.30148942 | I8: =E8/SUM(E8:F8) -> 0.23164954 | J8: 1.43 | K8: =J8/(1+(1-G8)*H8) -> 1.1808007
B9: Brainbees Solut. | D9: India | E9: =[1]Sheet1!P5 -> 1573.61 | F9: =[1]Sheet1!N5 -> 17454.38 | G9: 0.3 | H9: =E9/F9 -> 0.090155594 | I9: =E9/SUM(E9:F9) -> 0.082699749 | J9: 0 | K9: =J9/(1+(1-G9)*H9) -> 0
B10: Medplus Health | D10: India | E10: =[1]Sheet1!P6 -> 1029.75 | F10: =[1]Sheet1!N6 -> 10021.96 | G10: 0.3 | H10: =E10/F10 -> 0.10274936 | I10: =E10/SUM(E10:F10) -> 0.093175626 | J10: 0.72 | K10: =J10/(1+(1-G10)*H10) -> 0.67168906
F13: Average | G13: =AVERAGE(G6:G10) -> 0.3 | H13: =AVERAGE(H6:H10) -> 0.10136843 | I13: =AVERAGE(I6:I10) -> 0.083973791 | J13: =AVERAGE(J6:J10) -> 0.86445622
F14: Median | G14: =MEDIAN(G6:G10) -> 0.3 | H14: =MEDIAN(H6:H10) -> 0.090155594 | I14: =MEDIAN(I6:I10) -> 0.082699749 | J14: =MEDIAN(J6:J10) -> 1.0622811

Sheet DCF MODELLING
B3: Weighted Average Cost Of Capital
B5: All figures are in INR unless stated otherwise
B7: Peer Comps
G9: Debt/ | H9: Debt/ | I9: Levered | J9: Unlevered
B10: Name of the Company | C10: Country | D10: Equity | E10: debt | F10: Tax Rate 1 | G10: Equity | H10: Capital | I10: Beta 2 | J10: Beta 3
B12: Avenue Super. | C12: India | D12: =[1]Sheet1!N2 -> 281370.49 | E12: =[1]Sheet1!P2 -> 712.91 | F12: 0.3 | G12: =E12/D12 -> 0.0025337056 | H12: =E12/(SUM(D12:E12)) -> 0.0025273022 | I12: ='PEER COMPARISON'!J6 -> 1.0622811 | J12: =I12/(1+(1-F12)*G12) -> 1.0604004
B13: Trent | C13: India | D13: =[1]Sheet1!N3 -> 185816.8 | E13: =[1]Sheet1!P3 -> 1842.2 | F13: 0.3 | G13: =E13/D13 -> 0.0099140659 | H13: =E13/(SUM(D13:E13)) -> 0.0098167421 | I13: ='PEER COMPARISON'!J7 -> 1.11 | J13: =I13/(1+(1-F13)*G13) -> 1.1023499
B14: Aditya Bir. Fas. | C14: India | D14: =[1]Sheet1!N4 -> 33165.94 | E14: =[1]Sheet1!P4 -> 9999.18 | F14: 0.3 | G14: =E14/D14 -> 0.30148942 | H14: =E14/(SUM(D14:E14)) -> 0.23164954 | I14: ='PEER COMPARISON'!J8 -> 1.43 | J14: =I14/(1+(1-F14)*G14) -> 1.1808007
B15: Brainbees Solut. | C15: India | D15: =[1]Sheet1!N5 -> 17454.38 | E15: =[1]Sheet1!P5 -> 1573.61 | F15: 0.3 | G15: =E15/D15 -> 0.090155594 | H15: =E15/(SUM(D15:E15)) -> 0.082699749 | I15: ='PEER COMPARISON'!J9 -> 0 | J15: =I15/(1+(1-F15)*G15) -> 0
B16: Medplus Health | C16: India | D16: =[1]Sheet1!N6 -> 10021.96 | E16: =[1]Sheet1!P6 -> 1029.75 | F16: 0.3 | G16: =E16/D16 -> 0.10274936 | H16: =E16/(SUM(D16:E16)) -> 0.093175626 | I16: ='PEER COMPARISON'!J10 -> 0.72 | J16: =I16/(1+(1-F16)*G16) -> 0.67168906
E20: AVERAGE | F20: =AVERAGE(F12:F16) -> 0.3 | G20: =AVERAGE(G12:G16) -> 0.10136843 | H20: =AVERAGE(H12:H16) -> 0.083973791 | I20: =AVERAGE(I12:I16) -> 0.86445622 | J20: =AVERAGE(J12:J16) -> 0.80304801
E21: MEDIAN | F21: =MEDIAN(F12:F16) -> 0.3 | G21: =MEDIAN(G12:G16) -> 0.090155594 | H21: =MEDIAN(H12:H16) -> 0.082699749 | I21: =MEDIAN(I12:I16) -> 1.0622811 | J21: =MEDIAN(J12:J16) -> 1.0604004
B24: Cost of Debt | J24: Cost Of Equity
B26: Pre-Tax Cost of Debt | C26: =58/C34 -> 0.081356693 | J26: Risk Free Rate | K26: 0.0647
B27: Tax Rate | C27: 0.3 | J27: Equity Risk Premium | K27: =[3]Sheet1!$G$4-K26 -> 0.088648
B28: Post-Tax Cost of Debt | C28: =C26*(1-C27) -> 0.056949685 | J28: Levered Beta 4 | K28: 1.12
J29: Cost Of Equity | K29: =K26+K27*K28 -> 0.16398576
B31: Capital Structure | J31: Cost Of Equity
D33: Current | E33: Target | J33: Comp. median unlevered Beta | K33: =J21 -> 1.0604004
B34: Total Debt | C34: =E12 -> 712.91 | D34: =C34/C36 -> 0.0025273022 | E34: =H20 -> 0.083973791 | J34: target debt/equity | K34: =E34 -> 0.083973791
B35: Market Capitalization | C35: =D12 -> 281370.49 | D35: =D36-D34 -> 0.9974727 | E35: =E36-E34 -> 0.91602621 | J35: Tax Rate | K35: 0.3
B36: Total Capital | C36: =SUM(C34:C35) -> 282083.4 | D36: 1 | E36: 1 | J36: Levered Beta | K36: =K33*(1+(1-K35)*K34) -> 1.1227324
B38: debt/equity | D38: =D34/D35 -> 0.0025337056 | E38: =E34/E35 -> 0.091671821
B43: Weighted Average Cost Of Capital | J43: Notes
J44: 1. Tax rate considered as marginal tax rate for the country
B45: Debt | C45: =C28 -> 0.056949685 | D45: =E34 -> 0.083973791 | J45: 2.levered beta is based on 5 year monthly data
B46: Equity | C46: =K29 -> 0.16398576 | D46: =E35 -> 0.91602621 | J46: 3.unlevered data = levered beta/(1+(1-tax rate)*debt/equity)
B47: Weighted Average Cost Of Capital | D47: =SUMPRODUCT(C45:C46,D45:D46) -> 0.15499754 | J47: 4.levered beta = unlevered beta*(1+(1-tax rate)* debt/equity)

Sheet BETA CALCULATION
A2: AVENUE SUPERMART | F2: NIFTY 50
A3: Date | B3: Price | C3: Weakly Return | F3: Price | G3: Weakly Return
A4: 45018 | B4: 3496.1 | F4: 17599.15
A5: 45025 | B5: 3501.05 | C5: =B5/B4-1 -> 0.0014158634 | F5: 17828 | G5: =F5/F4-1 -> 0.013003469 | J5: BETA DRIFTIG
A6: 45032 | B6: 3455.9 | C6: =B6/B5-1 -> -0.012896131 | F6: 17624.05 | G6: =F6/F5-1 -> -0.01143987
A7: 45039 | B7: 3511.95 | C7: =B7/B6-1 -> 0.016218641 | F7: 18065 | G7: =F7/F6-1 -> 0.025019788 | J7: LEVERED RAW BETA | L7: =Q7 -> 1.0622811 | O7: BETA1 | Q7: =SLOPE(C5:C108,G5:G108) -> 1.0622811
A8: 45046 | B8: 3598.2 | C8: =B8/B7-1 -> 0.024559006 | F8: 18069 | G8: =F8/F7-1 -> 0.00022142264 | J8: RAW BETA WEIGHT | L8: 0.75 | O8: BETA2 | Q8: =COVAR(C5:C108,G5:G108)/VAR(G5:G108) -> 1.0520668 | R8: Cov of xy/variance of
A9: 45053 | B9: 3677.55 | C9: =B9/B8-1 -> 0.022052693 | F9: 18314.8 | G9: =F9/F8-1 -> 0.013603409 | J9: MARKET BETA | L9: 1 | O9: BETA3 | Q9: =N120 -> 1.0622811
A10: 45060 | B10: 3395.25 | C10: =B10/B9-1 -> -0.076763062 | F10: 18203.4 | G10: =F10/F9-1 -> -0.0060825125 | J10: MARKET BETA WEIGHT | L10: 0.25
A11: 45067 | B11: 3501.75 | C11: =B11/B10-1 -> 0.031367351 | F11: 18499.35 | G11: =F11/F10-1 -> 0.016257952
A12: 45074 | B12: 3531.6 | C12: =B12/B11-1 -> 0.0085243093 | F12: 18534.1 | G12: =F12/F11-1 -> 0.0018784444 | J12: ADJUSTED BETA | L12: =(L7*L8)+(L10*L9) -> 1.0467108
A13: 45081 | B13: 3632.1 | C13: =B13/B12-1 -> 0.028457356 | F13: 18563.4 | G13: =F13/F12-1 -> 0.0015808699
A14: 45088 | B14: 4085.6 | C14: =B14/B13-1 -> 0.1248589 | F14: 18826 | G14: =F14/F13-1 -> 0.014146115
A15: 45095 | B15: 3744.05 | C15: =B15/B14-1 -> -0.083598492 | F15: 18665.5 | G15: =F15/F14-1 -> -0.0085254435
A16: 45102 | B16: 3889.2 | C16: =B16/B15-1 -> 0.038768179 | F16: 19189.05 | G16: =F16/F15-1 -> 0.028049074
A17: 45109 | B17: 3808.95 | C17: =B17/B16-1 -> -0.020634064 | F17: 19331.8 | G17: =F17/F16-1 -> 0.0074391385 | J17: SUMARY OUTPUT
A18: 45116 | B18: 3838.75 | C18: =B18/B17-1 -> 0.0078236784 | F18: 19564.5 | G18: =F18/F17-1 -> 0.012037162
A19: 45123 | B19: 3675.7 | C19: =B19/B18-1 -> -0.042474764 | F19: 19745 | G19: =F19/F18-1 -> 0.0092258938 | J19: REGRESSION STATISTICS
A20: 45130 | B20: 3713.9 | C20: =B20/B19-1 -> 0.010392578 | F20: 19646.05 | G20: =F20/F19-1 -> -0.0050113953
A21: 45137 | B21: 3652.1 | C21: =B21/B20-1 -> -0.01664019 | F21: 19517 | G21: =F21/F20-1 -> -0.0065687505
A22: 45144 | B22: 3550.05 | C22: =B22/B21-1 -> -0.027942827 | F22: 19428.3 | G22: =F22/F21-1 -> -0.0045447559 | Q22: SUMMARY OUTPUT
A23: 45151 | B23: 3540.95 | C23: =B23/B22-1 -> -0.0025633442 | F23: 19310.15 | G23: =F23/F22-1 -> -0.006081335
A24: 45158 | B24: 3534.6 | C24: =B24/B23-1 -> -0.0017933041 | F24: 19265.8 | G24: =F24/F23-1 -> -0.0022967196 | Q24: Regression Statistics
A25: 45165 | B25: 3761.05 | C25: =B25/B24-1 -> 0.064066655 | F25: 19435.3 | G25: =F25/F24-1 -> 0.0087979736 | Q25: Multiple R | R25: 0.41785324
A26: 45172 | B26: 3782.4 | C26: =B26/B25-1 -> 0.0056766063 | F26: 19819.95 | G26: =F26/F25-1 -> 0.019791308 | Q26: R Square | R26: 0.17460133
A27: 45179 | B27: 3796 | C27: =B27/B26-1 -> 0.0035956007 | F27: 20192.35 | G27: =F27/F26-1 -> 0.018789149 | Q27: Adjusted R Square | R27: 0.16650918
A28: 45186 | B28: 3689.1 | C28: =B28/B27-1 -> -0.028161222 | F28: 19674.25 | G28: =F28/F27-1 -> -0.025658232 | Q28: Standard Error | R28: 0.037973143
A29: 45193 | B29: 3675.6 | C29: =B29/B28-1 -> -0.0036594291 | F29: 19638.3 | G29: =F29/F28-1 -> -0.0018272615 | Q29: Observations | R29: 104
A30: 45200 | B30: 3833.95 | C30: =B30/B29-1 -> 0.043081402 | F30: 19653.5 | G30: =F30/F29-1 -> 0.00077399775
A31: 45207 | B31: 3935.85 | C31: =B31/B30-1 -> 0.026578333 | F31: 19751.05 | G31: =F31/F30-1 -> 0.0049634925 | Q31: ANOVA
A32: 45214 | B32: 3749.5 | C32: =B32/B31-1 -> -0.047346825 | F32: 19542.65 | G32: =F32/F31-1 -> -0.010551338 | R32: df | S32: SS | T32: MS | U32: F | V32: Significance F
A33: 45221 | B33: 3665.45 | C33: =B33/B32-1 -> -0.022416322 | F33: 19047.25 | G33: =F33/F32-1 -> -0.025349684 | Q33: Regression | R33: 1 | S33: 0.031112652 | T33: 0.031112652 | U33: 21.576646 | V33: 1.0173947e-05
